<?xml version="1.0" ?>
<robot name="my_4wheel_robot" xmlns:xacro="http://www.ros.org/wiki/xacro">

  <material name="grey"><color rgba="0.7 0.7 0.7 1" /></material>
  <material name="green"><color rgba="0 0.6 0 1" /></material>
  <material name="white"><color rgba="1 1 1 1" /></material>

  <link name="base_footprint" />


  <link name="base_link">
    <visual>
      <geometry><box size="0.21 0.135 0.135" /></geometry>
      <origin xyz="0 0 0.08" rpy="0 0 0" />
      <material name="green" />
    </visual>
    <collision>
      <geometry><box size="0.21 0.135 0.135" /></geometry>
      <origin xyz="0 0 0.08" rpy="0 0 0" />
    </collision>
    <inertial>
      <mass value="2.0"/>
      <origin xyz="0 0 0.08" rpy="0 0 0"/>
      <inertia ixx="0.01" ixy="0" ixz="0" iyy="0.01" iyz="0" izz="0.01"/>
    </inertial>
  </link>

  <joint name="base_joint" type="fixed">
    <parent link="base_footprint" />
    <child link="base_link" />
    <origin xyz="0 0 0.0325" rpy="0 0 0"/>
  </joint>

  <gazebo reference="base_link">
    <material>Gazebo/Green</material>
    <mu1>0.2</mu1>
    <mu2>0.2</mu2>
  </gazebo>

  <link name="left_back_wheel">
    <visual>
      <geometry><cylinder radius="0.0325" length="0.025" /></geometry>
      <origin xyz="0 0 0" rpy="1.5708 0 0" />
      <material name="grey" />
    </visual>
    <collision>
      <geometry><cylinder radius="0.0325" length="0.025" /></geometry>
      <origin xyz="0 0 0" rpy="1.5708 0 0" />
    </collision>
    <inertial>
      <mass value="0.5"/>
      <inertia ixx="0.0001" ixy="0" ixz="0" iyy="0.0001" iyz="0" izz="0.0001"/>
    </inertial>
  </link>

  <joint name="left_back_wheel_joint" type="continuous">
    <parent link="base_link" />
    <child link="left_back_wheel" />
    <origin xyz="-0.0525 0.0775 0" rpy="0 0 0" />
    <axis xyz="0 1 0" />
  </joint>

  <gazebo reference="left_back_wheel">
    <material>Gazebo/Grey</material>
    <mu1>1.0</mu1><mu2>1.0</mu2>
    <kp>1000000.0</kp><kd>100.0</kd>
  </gazebo>

  <link name="right_back_wheel">
    <visual>
      <geometry><cylinder radius="0.0325" length="0.025" /></geometry>
      <origin xyz="0 0 0" rpy="1.5708 0 0" />
      <material name="grey" />
    </visual>
    <collision>
      <geometry><cylinder radius="0.0325" length="0.025" /></geometry>
      <origin xyz="0 0 0" rpy="1.5708 0 0" />
    </collision>
    <inertial>
      <mass value="0.5"/>
      <inertia ixx="0.0001" ixy="0" ixz="0" iyy="0.0001" iyz="0" izz="0.0001"/>
    </inertial>
  </link>

  <joint name="right_back_wheel_joint" type="continuous">
    <parent link="base_link" />
    <child link="right_back_wheel" />
    <origin xyz="-0.0525 -0.0775 0" rpy="0 0 0" />
    <axis xyz="0 1 0" />
  </joint>

  <gazebo reference="right_back_wheel">
    <material>Gazebo/Grey</material>
    <mu1>1.0</mu1><mu2>1.0</mu2>
    <kp>1000000.0</kp><kd>100.0</kd>
  </gazebo>

  <link name="left_front_wheel">
    <visual>
      <geometry><cylinder radius="0.0325" length="0.025" /></geometry>
      <origin xyz="0 0 0" rpy="1.5708 0 0" />
      <material name="grey" />
    </visual>
    <collision>
      <geometry><cylinder radius="0.0325" length="0.025" /></geometry>
      <origin xyz="0 0 0" rpy="1.5708 0 0" />
    </collision>
    <inertial>
      <mass value="0.5"/>
      <inertia ixx="0.0001" ixy="0" ixz="0" iyy="0.0001" iyz="0" izz="0.0001"/>
    </inertial>
  </link>

  <joint name="left_front_wheel_joint" type="continuous">
    <parent link="base_link" />
    <child link="left_front_wheel" />
    <origin xyz="0.0525 0.0775 0" rpy="0 0 0" />
    <axis xyz="0 1 0" />
  </joint>

  <gazebo reference="left_front_wheel">
    <material>Gazebo/Grey</material>
    <mu1>1.0</mu1><mu2>1.0</mu2>
    <kp>1000000.0</kp><kd>100.0</kd>
  </gazebo>

  <link name="right_front_wheel">
    <visual>
      <geometry><cylinder radius="0.0325" length="0.025" /></geometry>
      <origin xyz="0 0 0" rpy="1.5708 0 0" />
      <material name="grey" />
    </visual>
    <collision>
      <geometry><cylinder radius="0.0325" length="0.025" /></geometry>
      <origin xyz="0 0 0" rpy="1.5708 0 0" />
    </collision>
    <inertial>
      <mass value="0.5"/>
      <inertia ixx="0.0001" ixy="0" ixz="0" iyy="0.0001" iyz="0" izz="0.0001"/>
    </inertial>
  </link>

  <joint name="right_front_wheel_joint" type="continuous">
    <parent link="base_link" />
    <child link="right_front_wheel" />
    <origin xyz="0.0525 -0.0775 0" rpy="0 0 0" />
    <axis xyz="0 1 0" />
  </joint>

  <gazebo reference="right_front_wheel">
    <material>Gazebo/Grey</material>
    <mu1>1.0</mu1><mu2>1.0</mu2>
    <kp>1000000.0</kp><kd>100.0</kd>
  </gazebo>

  <link name="lidar">
    <visual>
      <geometry><cylinder radius="0.035" length="0.02" /></geometry>
      <material name="white"/>
    </visual>
    <collision>
      <geometry><cylinder radius="0.035" length="0.02" /></geometry>
    </collision>
    <inertial>
      <mass value="0.1"/>
      <inertia ixx="0.0001" ixy="0" ixz="0" iyy="0.0001" iyz="0" izz="0.0001"/>
    </inertial>
  </link>

  <joint name="base_lidar_joint" type="fixed">
    <parent link="base_link" />
    <child link="lidar" />
    <origin xyz="0 0 0.16" rpy="0 0 0" />
  </joint>

  <gazebo>
    <plugin name="skid_steer_drive" filename="libgazebo_ros_diff_drive.so">
      <ros><namespace>/</namespace></ros>
      <num_wheel_pairs>2</num_wheel_pairs>
      <left_joint>left_front_wheel_joint</left_joint>
      <left_joint>left_back_wheel_joint</left_joint>
      <right_joint>right_front_wheel_joint</right_joint>
      <right_joint>right_back_wheel_joint</right_joint>
      <wheel_separation>0.155</wheel_separation>
      <wheel_diameter>0.065</wheel_diameter>
      <publish_odom>true</publish_odom>
      <publish_odom_tf>true</publish_odom_tf>
      <publish_wheel_tf>true</publish_wheel_tf>
      <odometry_frame>odom</odometry_frame>
      <robot_base_frame>base_footprint</robot_base_frame>
    </plugin>
  </gazebo>

  <gazebo reference="lidar">
    <sensor name="laser" type="ray">
      <visualize>true</visualize>
      <update_rate>10</update_rate>
      <ray>
        <scan>
          <horizontal>
            <samples>360</samples>
            <min_angle>-3.14</min_angle>
            <max_angle>3.14</max_angle>
          </horizontal>
        </scan>
        <range><min>0.12</min><max>12.0</max></range>
      </ray>
      <plugin name="laser_controller" filename="libgazebo_ros_ray_sensor.so">
        <ros>
          <argument>~/out:=scan</argument>
          <qos>
            <topic name="scan">
              <publisher>
                <reliability>best_effort</reliability>
                <durability>volatile</durability>
                <history depth="1">keep_last</history>
              </publisher>
            </topic>
          </qos>
        </ros>
        <output_type>sensor_msgs/LaserScan</output_type>
        <frame_name>lidar</frame_name>
      </plugin>
    </sensor>
  </gazebo>

</robot>
